<mujoco model="simple_arm">
    <option gravity="0 0 -9.81" timestep="0.001"/>

    <worldbody>
        <body name="link1" pos="0 0 0">
            <inertial pos="0.5 0 0" mass="1.0" diaginertia="0.01 0.01 0.01"/>
            <joint name="shoulder" type="hinge" axis="0 0 1" damping="0.1"/>

            <body name="link2" pos="1.0 0 0">
                <inertial pos="0.25 0 0" mass="0.5" diaginertia="0.005 0.005 0.005"/>
                <joint name="elbow" type="slide" axis="1 0 0" damping="0.05"/>
            </body>
        </body>
    </worldbody>
</mujoco>
